<?xml version="1.0" encoding="utf-8"?>
<!-- This URDF was automatically created by SolidWorks to URDF Exporter! Originally created by Stephen Brawner (brawner@gmail.com) 
     Commit Version: 1.5.1-0-g916b5db  Build Version: 1.5.7152.31018
     For more information, please see http://wiki.ros.org/sw_urdf_exporter -->
<robot
  name="Mobile Robot urdf">
  <link
    name="base_link">
    <inertial>
      <origin
        xyz="-0.0932818046123113 0.248622421419087 0.148035881432924"
        rpy="0 0 0" />
      <mass
        value="5.68536204419266" />
      <inertia
        ixx="0.0461012423919062"
        ixy="2.44900119218913E-08"
        ixz="1.62170167989438E-07"
        iyy="0.0230236988866696"
        iyz="-1.99379837902682E-05"
        izz="0.0603619757567182" />
    </inertial>
    <visual>
      <origin
        xyz="0 0 0"
        rpy="0 0 0" />
      <geometry>
        <mesh
          filename="package://Mobile Robot urdf/meshes/base_link.STL" />
      </geometry>
      <material
        name="">
        <color
          rgba="0.792156862745098 0.819607843137255 0.933333333333333 1" />
      </material>
    </visual>
    <collision>
      <origin
        xyz="0 0 0"
        rpy="0 0 0" />
      <geometry>
        <mesh
          filename="package://Mobile Robot urdf/meshes/base_link.STL" />
      </geometry>
    </collision>
  </link>
  <link
    name="Right wheel">
    <inertial>
      <origin
        xyz="-1.38777878078145E-17 -0.005 0"
        rpy="0 0 0" />
      <mass
        value="0.311318231974914" />
      <inertia
        ixx="0.000782632376819195"
        ixy="-1.64007114091507E-19"
        ixz="-7.19717443273202E-20"
        iyy="0.00156010303265185"
        iyz="1.75796643917705E-19"
        izz="0.000782632376819195" />
    </inertial>
    <visual>
      <origin
        xyz="0 0 0"
        rpy="0 0 0" />
      <geometry>
        <mesh
          filename="package://Mobile Robot urdf/meshes/Right wheel.STL" />
      </geometry>
      <material
        name="">
        <color
          rgba="0.792156862745098 0.819607843137255 0.933333333333333 1" />
      </material>
    </visual>
    <collision>
      <origin
        xyz="0 0 0"
        rpy="0 0 0" />
      <geometry>
        <mesh
          filename="package://Mobile Robot urdf/meshes/Right wheel.STL" />
      </geometry>
    </collision>
  </link>
  <joint
    name="Right joint"
    type="continuous">
    <origin
      xyz="-0.19528 0.14862 0.12408"
      rpy="1.5708 -1.5708 0" />
    <parent
      link="base_link" />
    <child
      link="Right wheel" />
    <axis
      xyz="0 1 0" />
  </joint>
  <link
    name="Left wheel">
    <inertial>
      <origin
        xyz="-1.38777878078145E-17 0.00500000000000002 0"
        rpy="0 0 0" />
      <mass
        value="0.311318231974914" />
      <inertia
        ixx="0.000782632376819195"
        ixy="4.46300362903685E-20"
        ixz="-5.42101086242752E-20"
        iyy="0.00156010303265185"
        iyz="-4.82280036763924E-20"
        izz="0.000782632376819195" />
    </inertial>
    <visual>
      <origin
        xyz="0 0 0"
        rpy="0 0 0" />
      <geometry>
        <mesh
          filename="package://Mobile Robot urdf/meshes/Left wheel.STL" />
      </geometry>
      <material
        name="">
        <color
          rgba="0.792156862745098 0.819607843137255 0.933333333333333 1" />
      </material>
    </visual>
    <collision>
      <origin
        xyz="0 0 0"
        rpy="0 0 0" />
      <geometry>
        <mesh
          filename="package://Mobile Robot urdf/meshes/Left wheel.STL" />
      </geometry>
    </collision>
  </link>
  <joint
    name="Left joint"
    type="continuous">
    <origin
      xyz="0.0087188 0.14862 0.12408"
      rpy="0 -1.0364 -1.5708" />
    <parent
      link="base_link" />
    <child
      link="Left wheel" />
    <axis
      xyz="0 -1 0" />
  </joint>
  <link
    name="wheel holder">
    <inertial>
      <origin
        xyz="0 -0.0344478094730443 0"
        rpy="0 0 0" />
      <mass
        value="0.0385018272527705" />
      <inertia
        ixx="1.84552215695491E-05"
        ixy="1.02223341060484E-21"
        ixz="2.11758236813575E-21"
        iyy="1.07969223394932E-05"
        iyz="-8.15898875512751E-22"
        izz="1.49331507863245E-05" />
    </inertial>
    <visual>
      <origin
        xyz="0 0 0"
        rpy="0 0 0" />
      <geometry>
        <mesh
          filename="package://Mobile Robot urdf/meshes/wheel holder.STL" />
      </geometry>
      <material
        name="">
        <color
          rgba="0.647058823529412 0.619607843137255 0.588235294117647 1" />
      </material>
    </visual>
    <collision>
      <origin
        xyz="0 0 0"
        rpy="0 0 0" />
      <geometry>
        <mesh
          filename="package://Mobile Robot urdf/meshes/wheel holder.STL" />
      </geometry>
    </collision>
  </link>
  <joint
    name="wheel holder to base joint"
    type="continuous">
    <origin
      xyz="-0.093281166557301 0.348621605332735 0.0442217325358986"
      rpy="-1.5707963267949 0 -1.85769169657717" />
    <parent
      link="base_link" />
    <child
      link="wheel holder" />
    <axis
      xyz="0 1 0" />
  </joint>
  <link
    name="Front wheel">
    <inertial>
      <origin
        xyz="-2.77555756156289E-17 2.22044604925031E-16 0"
        rpy="0 0 0" />
      <mass
        value="0.0261883950379585" />
      <inertia
        ixx="6.4118385495969E-06"
        ixy="-2.69991751937308E-21"
        ixz="4.2351647362715E-22"
        iyy="1.2395183022203E-05"
        iyz="-1.16467030247466E-21"
        izz="6.41183854959689E-06" />
    </inertial>
    <visual>
      <origin
        xyz="0 0 0"
        rpy="0 0 0" />
      <geometry>
        <mesh
          filename="package://Mobile Robot urdf/meshes/Front wheel.STL" />
      </geometry>
      <material
        name="">
        <color
          rgba="0.792156862745098 0.819607843137255 0.933333333333333 1" />
      </material>
    </visual>
    <collision>
      <origin
        xyz="0 0 0"
        rpy="0 0 0" />
      <geometry>
        <mesh
          filename="package://Mobile Robot urdf/meshes/Front wheel.STL" />
      </geometry>
    </collision>
  </link>
  <joint
    name="Front wheel to holder joint"
    type="continuous">
    <origin
      xyz="0 -0.00985606670833084 0"
      rpy="-1.5707963267949 0 1.00050049811449" />
    <parent
      link="wheel holder" />
    <child
      link="Front wheel" />
    <axis
      xyz="0 1 0" />
  </joint>
</robot>