<?xml version="1.0" encoding="utf-8"?>
<!-- This URDF was automatically created by SolidWorks to URDF Exporter! Originally created by Stephen Brawner (brawner@gmail.com) 
     Commit Version: 1.5.1-0-g916b5db  Build Version: 1.5.7152.31018
     For more information, please see http://wiki.ros.org/sw_urdf_exporter -->
<robot
  name="Mobile Robot">
  <link
    name="Body">
    <inertial>
      <origin
        xyz="0.0932818046123113 0.148035881432924 0.248622421419087"
        rpy="0 0 0" />
      <mass
        value="5.68536204419266" />
      <inertia
        ixx="0.0461012423919062"
        ixy="-1.6217016798956E-07"
        ixz="-2.44900119206539E-08"
        iyy="0.0603619757567182"
        iyz="-1.99379837902658E-05"
        izz="0.0230236988866696" />
    </inertial>
    <visual>
      <origin
        xyz="0 0 0"
        rpy="0 0 0" />
      <geometry>
        <mesh
          filename="package://Mobile Robot/meshes/Body.STL" />
      </geometry>
      <material
        name="">
        <color
          rgba="0.792156862745098 0.819607843137255 0.933333333333333 1" />
      </material>
    </visual>
    <collision>
      <origin
        xyz="0 0 0"
        rpy="0 0 0" />
      <geometry>
        <mesh
          filename="package://Mobile Robot/meshes/Body.STL" />
      </geometry>
    </collision>
  </link>
  <link
    name="Right_wheel">
    <inertial>
      <origin
        xyz="-4.0728E-05 -0.01 0.00017127"
        rpy="0 0 0" />
      <mass
        value="0.45892" />
      <inertia
        ixx="0.0013018"
        ixy="-3.8745E-19"
        ixz="1.1691E-06"
        iyy="0.0025685"
        iyz="6.8664E-22"
        izz="0.0012971" />
    </inertial>
    <visual>
      <origin
        xyz="0 0 0"
        rpy="0 0 0" />
      <geometry>
        <mesh
          filename="package://Mobile Robot/meshes/Right_wheel.STL" />
      </geometry>
      <material
        name="">
        <color
          rgba="0.79216 0.81961 0.93333 1" />
      </material>
    </visual>
    <collision>
      <origin
        xyz="0 0 0"
        rpy="0 0 0" />
      <geometry>
        <mesh
          filename="package://Mobile Robot/meshes/Right_wheel.STL" />
      </geometry>
    </collision>
  </link>
  <joint
    name="Right_joint"
    type="continuous">
    <origin
      xyz="0.19528 -0.14862 0.12408"
      rpy="0 -0.79207 1.5708" />
    <parent
      link="Body" />
    <child
      link="Right_wheel" />
    <axis
      xyz="0 1 0" />
  </joint>
  <link
    name="Left_wheel">
    <inertial>
      <origin
        xyz="-4.0728E-05 -0.01 0.00017127"
        rpy="0 0 0" />
      <mass
        value="0.45892" />
      <inertia
        ixx="0.0013018"
        ixy="-5.8747E-20"
        ixz="1.1691E-06"
        iyy="0.0025685"
        iyz="-8.7265E-20"
        izz="0.0012971" />
    </inertial>
    <visual>
      <origin
        xyz="0 0 0"
        rpy="0 0 0" />
      <geometry>
        <mesh
          filename="package://Mobile Robot/meshes/Left_wheel.STL" />
      </geometry>
      <material
        name="">
        <color
          rgba="0.79216 0.81961 0.93333 1" />
      </material>
    </visual>
    <collision>
      <origin
        xyz="0 0 0"
        rpy="0 0 0" />
      <geometry>
        <mesh
          filename="package://Mobile Robot/meshes/Left_wheel.STL" />
      </geometry>
    </collision>
  </link>
  <joint
    name="Left_joint"
    type="continuous">
    <origin
      xyz="-0.0087188 -0.14862 0.12408"
      rpy="3.1416 -1.2295 1.5708" />
    <parent
      link="Body" />
    <child
      link="Left_wheel" />
    <axis
      xyz="0 -1 0" />
  </joint>
  <link
    name="Front_wheel_holder">
    <inertial>
      <origin
        xyz="-0.0026796 -0.034448 -2.3592E-16"
        rpy="0 0 0" />
      <mass
        value="0.038502" />
      <inertia
        ixx="1.8455E-05"
        ixy="1.3766E-06"
        ixz="4.574E-20"
        iyy="1.1036E-05"
        iyz="-1.2493E-20"
        izz="1.5173E-05" />
    </inertial>
    <visual>
      <origin
        xyz="0 0 0"
        rpy="0 0 0" />
      <geometry>
        <mesh
          filename="package://Mobile Robot/meshes/Front_wheel_holder.STL" />
      </geometry>
      <material
        name="">
        <color
          rgba="0.64706 0.61961 0.58824 1" />
      </material>
    </visual>
    <collision>
      <origin
        xyz="0 0 0"
        rpy="0 0 0" />
      <geometry>
        <mesh
          filename="package://Mobile Robot/meshes/Front_wheel_holder.STL" />
      </geometry>
    </collision>
  </link>
  <joint
    name="Wheel_holder to Body"
    type="continuous">
    <origin
      xyz="0.093281 -0.34862 0.044222"
      rpy="-1.5708 0 1.5978" />
    <parent
      link="Body" />
    <child
      link="Front_wheel_holder" />
    <axis
      xyz="0 1 0" />
  </joint>
  <link
    name="Front_wheel">
    <inertial>
      <origin
        xyz="0 0 0"
        rpy="0 0 0" />
      <mass
        value="0.021305" />
      <inertia
        ixx="5.5317E-06"
        ixy="4.5793E-21"
        ixz="-5.294E-21"
        iyy="1.0716E-05"
        iyz="2.283E-21"
        izz="5.5317E-06" />
    </inertial>
    <visual>
      <origin
        xyz="0 0 0"
        rpy="0 0 0" />
      <geometry>
        <mesh
          filename="package://Mobile Robot/meshes/Front_wheel.STL" />
      </geometry>
      <material
        name="">
        <color
          rgba="0.79216 0.81961 0.93333 1" />
      </material>
    </visual>
    <collision>
      <origin
        xyz="0 0 0"
        rpy="0 0 0" />
      <geometry>
        <mesh
          filename="package://Mobile Robot/meshes/Front_wheel.STL" />
      </geometry>
    </collision>
  </link>
  <joint
    name="Front_wheel to holder"
    type="continuous">
    <origin
      xyz="-0.005 -0.0098561 0"
      rpy="-1.5708 0 -0.39471" />
    <parent
      link="Front_wheel_holder" />
    <child
      link="Front_wheel" />
    <axis
      xyz="0 1 0" />
  </joint>
</robot>